Workbook

Sheet Instructions
B2: WEEKLY CASH FLOW SURVIVAL WORKSHEET
B3: ="Currently projecting "&TEXT(StartDate,"mmm d, yyyy")&" to "&TEXT(StartDate+90,"mmm d, yyyy")&" from a beginning balance of "&TEXT(BeginningBalance,"$#,##0.00")&"." -> Currently projecting Aug 15, 2026 to Nov 13, 2026 from a beginning balance of $228.41.
B5: THE FIVE PLACES YOU TYPE
B6: Cash Flow, E5–E8 | C6: ="Beginning balance "&TEXT(BeginningBalance,"$#,##0.00")&", start date "&TEXT(StartDate,"mmm d, yyyy")&", cushion "&TEXT(MinCushion,"$#,##0.00")&", expected everyday spending "&TEXT(WeeklySpend,"$#,##0.00")&" a week. Change any of these and the whole workbook follows." -> Beginning balance $228.41, start date Aug 15, 2026, cushion $200.00, expected everyday spending $400.00 a week. Change any of these and the whole workbook follows.
B7: Recurring | C7: Every bill and paycheck that repeats. Edit a row, add one in the first empty row, or set Active to No to retire it without losing the record. The Needs Attention column tells you when something is incomplete.
B8: Cash Flow, week blocks | C8: The variable-expense rows in each week: description, date, amount. Everything you actually spend goes here.
B9: Paid Log | C9: What a scheduled bill or paycheck really came to. Keyed to the transaction, so it stays put however the schedule re-sorts.
B10: Overrides | C10: A one-off different date or amount for a single occurrence. Delete the row to go back to normal.
B12: HOW TO READ IT
B13: ACTUAL vs FORECAST | C13: Every transaction row is labelled. ACTUAL has already happened or been logged; FORECAST is still expected.
B14: Status | C14: PAID and OK are green. DUE and TIGHT are amber. PAST DUE and SHORTFALL are red. TIGHT means above zero but under your cushion.
B15: Lowest In Week | C15: The worst moment inside a week, not just where it ends. A week can close healthy having gone under midweek, so this is what Status is judged on.
B16: Weekly Surplus | C16: The week standing alone — money in less all spending, nothing carried in. Carried Forward is shown separately.
B17: Colours | C17: Blue text on yellow means you type it. Everything else is calculated.
B19: RULES WORTH KNOWING
B20: Next Due Date | C20: The next occurrence you have NOT paid. A date in the past is fine — it shows in the first period as PAST DUE. Only move it forward once the money has actually moved.
B21: Dates | C21: Type 8/21/2026, not 821. A bare 821 is the number 821, which Excel reads as a date in 1902 and the row disappears. The Needs Attention column catches this.
B22: Start date | C22: ="Any weekday works. Yours begins on a "&TEXT(StartDate,"dddd")&", so every period runs "&TEXT(StartDate,"ddd")&" to "&TEXT(StartDate+6,"ddd")&"." -> Any weekday works. Yours begins on a Saturday, so every period runs Sat to Fri.
B23: Everyday spending | C23: Weeks with nothing logged are topped up to your expected weekly figure, so an untouched future week is never forecast at zero. Log more than it and the top-up falls away.
B24: Schedule tab | C24: The engine that turns recurring rules into dated occurrences. Safe to look at, protected against typing.
B26: ASSUMPTIONS ON RECORD
B27: • | C27: Recurring items were transcribed from the user's budget-app screenshots, August 2026. Nothing was invented.
B28: • | C28: Amounts are positive numbers; the Type column decides the direction.
B29: • | C29: ="Compunnel is entered at "&TEXT(INDEX(Recurring!$D:$D,MATCH("Compunnel*",Recurring!$B:$B,0)),"$#,##0.00")&", the low end of a paycheck that varies by about $45. A survival sheet plans on the smaller number." -> Compunnel is entered at $745.00, the low end of a paycheck that varies by about $45. A survival sheet plans on the smaller number.
B30: • | C30: Microsoft is active with no amount. It is flagged rather than guessed — put the real figure on the Recurring tab.
B31: • | C31: The Central Maine Power payment plan is billed on the CMP statement, not paid separately, so it is set to Active = No. The September bill of $183.69 already includes the $65 installment. The $163.50 base was itself a full bill under the older $43.87 installment, so October and November may run about $20 light until each real bill arrives.

Sheet Recurring
B1: RECURRING TRANSACTIONS
B2: Edit any row, or add a new one in the first empty row. Blue cells are yours to type in; the Cash Flow tab updates itself.
A4: ID | B4: Description | C4: Type | D4: Amount | E4: Frequency | F4: Next Due Date | G4: Weekend Rule | H4: Active | I4: Category | J4: Notes | K4: Needs Attention
A5: 1 | B5: Bruno's Restaurant (paycheck) | C5: Income | D5: 90 | E5: Weekly | F5: 46253 | G5: None | H5: Yes | I5: Wages | K5: =IF($B5="","",IF($H5<>"Yes","",IF(OR($D5="",$D5=0),"! No amount — this will project as $0",IF($F5="","! No next due date",IF(NOT(ISNUMBER($F5)),"! Next due date is not a date — type it as 8/21/2026",IF($E5="","! No frequency chosen",IF($F5<StartDate-90,"! "&TEXT($F5,"mmm d, yyyy")&" is too far back to appear",IF($F5>StartDate+730,"! "&TEXT($F5,"mmm d, yyyy")&" is years away — check it",IF($F5>StartDate+90,"beyond the 13-week window","")))))))))
A6: 2 | B6: Compunnel Software (paycheck) | C6: Income | D6: 745 | E6: Weekly | F6: 46255 | G6: None | H6: Yes | I6: Wages | K6: =IF($B6="","",IF($H6<>"Yes","",IF(OR($D6="",$D6=0),"! No amount — this will project as $0",IF($F6="","! No next due date",IF(NOT(ISNUMBER($F6)),"! Next due date is not a date — type it as 8/21/2026",IF($E6="","! No frequency chosen",IF($F6<StartDate-90,"! "&TEXT($F6,"mmm d, yyyy")&" is too far back to appear",IF($F6>StartDate+730,"! "&TEXT($F6,"mmm d, yyyy")&" is years away — check it",IF($F6>StartDate+90,"beyond the 13-week window","")))))))))
A7: 3 | B7: Apple: Claude | C7: Expense | D7: 21.1 | E7: Monthly | F7: 46269 | G7: None | H7: Yes | I7: Subscriptions | K7: =IF($B7="","",IF($H7<>"Yes","",IF(OR($D7="",$D7=0),"! No amount — this will project as $0",IF($F7="","! No next due date",IF(NOT(ISNUMBER($F7)),"! Next due date is not a date — type it as 8/21/2026",IF($E7="","! No frequency chosen",IF($F7<StartDate-90,"! "&TEXT($F7,"mmm d, yyyy")&" is too far back to appear",IF($F7>StartDate+730,"! "&TEXT($F7,"mmm d, yyyy")&" is years away — check it",IF($F7>StartDate+90,"beyond the 13-week window","")))))))))
A8: 4 | B8: OpenAI | C8: Expense | D8: 20 | E8: Monthly | F8: 46270 | G8: None | H8: Yes | I8: Subscriptions | K8: =IF($B8="","",IF($H8<>"Yes","",IF(OR($D8="",$D8=0),"! No amount — this will project as $0",IF($F8="","! No next due date",IF(NOT(ISNUMBER($F8)),"! Next due date is not a date — type it as 8/21/2026",IF($E8="","! No frequency chosen",IF($F8<StartDate-90,"! "&TEXT($F8,"mmm d, yyyy")&" is too far back to appear",IF($F8>StartDate+730,"! "&TEXT($F8,"mmm d, yyyy")&" is years away — check it",IF($F8>StartDate+90,"beyond the 13-week window","")))))))))
A9: 5 | B9: Obsidian | C9: Expense | D9: 10 | E9: Monthly | F9: 46270 | G9: None | H9: Yes | I9: Subscriptions | K9: =IF($B9="","",IF($H9<>"Yes","",IF(OR($D9="",$D9=0),"! No amount — this will project as $0",IF($F9="","! No next due date",IF(NOT(ISNUMBER($F9)),"! Next due date is not a date — type it as 8/21/2026",IF($E9="","! No frequency chosen",IF($F9<StartDate-90,"! "&TEXT($F9,"mmm d, yyyy")&" is too far back to appear",IF($F9>StartDate+730,"! "&TEXT($F9,"mmm d, yyyy")&" is years away — check it",IF($F9>StartDate+90,"beyond the 13-week window","")))))))))
A10: 6 | B10: Google One | C10: Expense | D10: 4.99 | E10: Monthly | F10: 46272 | G10: None | H10: Yes | I10: Subscriptions | K10: =IF($B10="","",IF($H10<>"Yes","",IF(OR($D10="",$D10=0),"! No amount — this will project as $0",IF($F10="","! No next due date",IF(NOT(ISNUMBER($F10)),"! Next due date is not a date — type it as 8/21/2026",IF($E10="","! No frequency chosen",IF($F10<StartDate-90,"! "&TEXT($F10,"mmm d, yyyy")&" is too far back to appear",IF($F10>StartDate+730,"! "&TEXT($F10,"mmm d, yyyy")&" is years away — check it",IF($F10>StartDate+90,"beyond the 13-week window","")))))))))
A11: 7 | B11: Upstart (loan) | C11: Expense | D11: 500 | E11: Monthly | F11: 46272 | G11: None | H11: Yes | I11: Debt | K11: =IF($B11="","",IF($H11<>"Yes","",IF(OR($D11="",$D11=0),"! No amount — this will project as $0",IF($F11="","! No next due date",IF(NOT(ISNUMBER($F11)),"! Next due date is not a date — type it as 8/21/2026",IF($E11="","! No frequency chosen",IF($F11<StartDate-90,"! "&TEXT($F11,"mmm d, yyyy")&" is too far back to appear",IF($F11>StartDate+730,"! "&TEXT($F11,"mmm d, yyyy")&" is years away — check it",IF($F11>StartDate+90,"beyond the 13-week window","")))))))))
A12: 8 | B12: Central Maine Power Co. | C12: Expense | D12: 163.5 | E12: Monthly | F12: 46273 | G12: None | H12: Yes | I12: Utilities | K12: =IF($B12="","",IF($H12<>"Yes","",IF(OR($D12="",$D12=0),"! No amount — this will project as $0",IF($F12="","! No next due date",IF(NOT(ISNUMBER($F12)),"! Next due date is not a date — type it as 8/21/2026",IF($E12="","! No frequency chosen",IF($F12<StartDate-90,"! "&TEXT($F12,"mmm d, yyyy")&" is too far back to appear",IF($F12>StartDate+730,"! "&TEXT($F12,"mmm d, yyyy")&" is years away — check it",IF($F12>StartDate+90,"beyond the 13-week window","")))))))))
A13: 9 | B13: Apple: iCloud | C13: Expense | D13: 2.99 | E13: Monthly | F13: 46278 | G13: None | H13: Yes | I13: Subscriptions | K13: =IF($B13="","",IF($H13<>"Yes","",IF(OR($D13="",$D13=0),"! No amount — this will project as $0",IF($F13="","! No next due date",IF(NOT(ISNUMBER($F13)),"! Next due date is not a date — type it as 8/21/2026",IF($E13="","! No frequency chosen",IF($F13<StartDate-90,"! "&TEXT($F13,"mmm d, yyyy")&" is too far back to appear",IF($F13>StartDate+730,"! "&TEXT($F13,"mmm d, yyyy")&" is years away — check it",IF($F13>StartDate+90,"beyond the 13-week window","")))))))))
A14: 10 | B14: Patrick Rombalski (rent) | C14: Expense | D14: 350 | E14: Twice a Month | F14: 46265 | G14: Move Before | H14: Yes | I14: Housing | K14: =IF($B14="","",IF($H14<>"Yes","",IF(OR($D14="",$D14=0),"! No amount — this will project as $0",IF($F14="","! No next due date",IF(NOT(ISNUMBER($F14)),"! Next due date is not a date — type it as 8/21/2026",IF($E14="","! No frequency chosen",IF($F14<StartDate-90,"! "&TEXT($F14,"mmm d, yyyy")&" is too far back to appear",IF($F14>StartDate+730,"! "&TEXT($F14,"mmm d, yyyy")&" is years away — check it",IF($F14>StartDate+90,"beyond the 13-week window","")))))))))
A15: 11 | B15: Spectrum | C15: Expense | D15: 171.1 | E15: Monthly | F15: 46255 | G15: None | H15: Yes | I15: Utilities | K15: =IF($B15="","",IF($H15<>"Yes","",IF(OR($D15="",$D15=0),"! No amount — this will project as $0",IF($F15="","! No next due date",IF(NOT(ISNUMBER($F15)),"! Next due date is not a date — type it as 8/21/2026",IF($E15="","! No frequency chosen",IF($F15<StartDate-90,"! "&TEXT($F15,"mmm d, yyyy")&" is too far back to appear",IF($F15>StartDate+730,"! "&TEXT($F15,"mmm d, yyyy")&" is years away — check it",IF($F15>StartDate+90,"beyond the 13-week window","")))))))))
A16: 12 | B16: Maine Revenue Services | C16: Expense | D16: 45 | E16: Monthly | F16: 46250 | G16: None | H16: Yes | I16: Taxes | K16: =IF($B16="","",IF($H16<>"Yes","",IF(OR($D16="",$D16=0),"! No amount — this will project as $0",IF($F16="","! No next due date",IF(NOT(ISNUMBER($F16)),"! Next due date is not a date — type it as 8/21/2026",IF($E16="","! No frequency chosen",IF($F16<StartDate-90,"! "&TEXT($F16,"mmm d, yyyy")&" is too far back to appear",IF($F16>StartDate+730,"! "&TEXT($F16,"mmm d, yyyy")&" is years away — check it",IF($F16>StartDate+90,"beyond the 13-week window","")))))))))
A17: 13 | B17: Metal Copy | C17: Expense | E17: Monthly | F17: 46252 | G17: None | H17: No | I17: Subscriptions | J17: Cancelled Aug 2026 | K17: =IF($B17="","",IF($H17<>"Yes","",IF(OR($D17="",$D17=0),"! No amount — this will project as $0",IF($F17="","! No next due date",IF(NOT(ISNUMBER($F17)),"! Next due date is not a date — type it as 8/21/2026",IF($E17="","! No frequency chosen",IF($F17<StartDate-90,"! "&TEXT($F17,"mmm d, yyyy")&" is too far back to appear",IF($F17>StartDate+730,"! "&TEXT($F17,"mmm d, yyyy")&" is years away — check it",IF($F17>StartDate+90,"beyond the 13-week window","")))))))))
A18: 14 | B18: Microsoft | C18: Expense | D18: 13.7 | E18: Monthly | F18: 46256 | G18: None | H18: Yes | I18: Subscriptions | K18: =IF($B18="","",IF($H18<>"Yes","",IF(OR($D18="",$D18=0),"! No amount — this will project as $0",IF($F18="","! No next due date",IF(NOT(ISNUMBER($F18)),"! Next due date is not a date — type it as 8/21/2026",IF($E18="","! No frequency chosen",IF($F18<StartDate-90,"! "&TEXT($F18,"mmm d, yyyy")&" is too far back to appear",IF($F18>StartDate+730,"! "&TEXT($F18,"mmm d, yyyy")&" is years away — check it",IF($F18>StartDate+90,"beyond the 13-week window","")))))))))
A19: 15 | B19: Central Maine Power: Payment Plan | C19: Expense | D19: 65 | E19: Monthly | F19: 46273 | G19: None | H19: No | I19: Utilities | J19: Billed on the CMP statement, not paid separately - folded into Central Maine Power Co. | K19: =IF($B19="","",IF($H19<>"Yes","",IF(OR($D19="",$D19=0),"! No amount — this will project as $0",IF($F19="","! No next due date",IF(NOT(ISNUMBER($F19)),"! Next due date is not a date — type it as 8/21/2026",IF($E19="","! No frequency chosen",IF($F19<StartDate-90,"! "&TEXT($F19,"mmm d, yyyy")&" is too far back to appear",IF($F19>StartDate+730,"! "&TEXT($F19,"mmm d, yyyy")&" is years away — check it",IF($F19>StartDate+90,"beyond the 13-week window","")))))))))
A20: 16 | B20: Maine Revenue Services (2) | C20: Expense | D20: 150 | E20: Monthly | F20: 46264 | G20: None | H20: Yes | I20: Taxes | K20: =IF($B20="","",IF($H20<>"Yes","",IF(OR($D20="",$D20=0),"! No amount — this will project as $0",IF($F20="","! No next due date",IF(NOT(ISNUMBER($F20)),"! Next due date is not a date — type it as 8/21/2026",IF($E20="","! No frequency chosen",IF($F20<StartDate-90,"! "&TEXT($F20,"mmm d, yyyy")&" is too far back to appear",IF($F20>StartDate+730,"! "&TEXT($F20,"mmm d, yyyy")&" is years away — check it",IF($F20>StartDate+90,"beyond the 13-week window","")))))))))
A21: 17 | B21: Progressive Insurance | C21: Expense | D21: 143.37 | E21: Monthly | F21: 46265 | G21: None | H21: Yes | I21: Insurance | K21: =IF($B21="","",IF($H21<>"Yes","",IF(OR($D21="",$D21=0),"! No amount — this will project as $0",IF($F21="","! No next due date",IF(NOT(ISNUMBER($F21)),"! Next due date is not a date — type it as 8/21/2026",IF($E21="","! No frequency chosen",IF($F21<StartDate-90,"! "&TEXT($F21,"mmm d, yyyy")&" is too far back to appear",IF($F21>StartDate+730,"! "&TEXT($F21,"mmm d, yyyy")&" is years away — check it",IF($F21>StartDate+90,"beyond the 13-week window","")))))))))
A22: 18 | B22: School clothes (back to school) | C22: Expense | D22: 300 | E22: One Time | F22: 46256 | G22: None | H22: Yes | I22: Shopping | J22: One-off, paid today | K22: =IF($B22="","",IF($H22<>"Yes","",IF(OR($D22="",$D22=0),"! No amount — this will project as $0",IF($F22="","! No next due date",IF(NOT(ISNUMBER($F22)),"! Next due date is not a date — type it as 8/21/2026",IF($E22="","! No frequency chosen",IF($F22<StartDate-90,"! "&TEXT($F22,"mmm d, yyyy")&" is too far back to appear",IF($F22>StartDate+730,"! "&TEXT($F22,"mmm d, yyyy")&" is years away — check it",IF($F22>StartDate+90,"beyond the 13-week window","")))))))))
A23: 19 | K23: =IF($B23="","",IF($H23<>"Yes","",IF(OR($D23="",$D23=0),"! No amount — this will project as $0",IF($F23="","! No next due date",IF(NOT(ISNUMBER($F23)),"! Next due date is not a date — type it as 8/21/2026",IF($E23="","! No frequency chosen",IF($F23<StartDate-90,"! "&TEXT($F23,"mmm d, yyyy")&" is too far back to appear",IF($F23>StartDate+730,"! "&TEXT($F23,"mmm d, yyyy")&" is years away — check it",IF($F23>StartDate+90,"beyond the 13-week window","")))))))))
A24: 20 | K24: =IF($B24="","",IF($H24<>"Yes","",IF(OR($D24="",$D24=0),"! No amount — this will project as $0",IF($F24="","! No next due date",IF(NOT(ISNUMBER($F24)),"! Next due date is not a date — type it as 8/21/2026",IF($E24="","! No frequency chosen",IF($F24<StartDate-90,"! "&TEXT($F24,"mmm d, yyyy")&" is too far back to appear",IF($F24>StartDate+730,"! "&TEXT($F24,"mmm d, yyyy")&" is years away — check it",IF($F24>StartDate+90,"beyond the 13-week window","")))))))))
A25: 21 | K25: =IF($B25="","",IF($H25<>"Yes","",IF(OR($D25="",$D25=0),"! No amount — this will project as $0",IF($F25="","! No next due date",IF(NOT(ISNUMBER($F25)),"! Next due date is not a date — type it as 8/21/2026",IF($E25="","! No frequency chosen",IF($F25<StartDate-90,"! "&TEXT($F25,"mmm d, yyyy")&" is too far back to appear",IF($F25>StartDate+730,"! "&TEXT($F25,"mmm d, yyyy")&" is years away — check it",IF($F25>StartDate+90,"beyond the 13-week window","")))))))))
A26: 22 | K26: =IF($B26="","",IF($H26<>"Yes","",IF(OR($D26="",$D26=0),"! No amount — this will project as $0",IF($F26="","! No next due date",IF(NOT(ISNUMBER($F26)),"! Next due date is not a date — type it as 8/21/2026",IF($E26="","! No frequency chosen",IF($F26<StartDate-90,"! "&TEXT($F26,"mmm d, yyyy")&" is too far back to appear",IF($F26>StartDate+730,"! "&TEXT($F26,"mmm d, yyyy")&" is years away — check it",IF($F26>StartDate+90,"beyond the 13-week window","")))))))))
A27: 23 | K27: =IF($B27="","",IF($H27<>"Yes","",IF(OR($D27="",$D27=0),"! No amount — this will project as $0",IF($F27="","! No next due date",IF(NOT(ISNUMBER($F27)),"! Next due date is not a date — type it as 8/21/2026",IF($E27="","! No frequency chosen",IF($F27<StartDate-90,"! "&TEXT($F27,"mmm d, yyyy")&" is too far back to appear",IF($F27>StartDate+730,"! "&TEXT($F27,"mmm d, yyyy")&" is years away — check it",IF($F27>StartDate+90,"beyond the 13-week window","")))))))))
A28: 24 | K28: =IF($B28="","",IF($H28<>"Yes","",IF(OR($D28="",$D28=0),"! No amount — this will project as $0",IF($F28="","! No next due date",IF(NOT(ISNUMBER($F28)),"! Next due date is not a date — type it as 8/21/2026",IF($E28="","! No frequency chosen",IF($F28<StartDate-90,"! "&TEXT($F28,"mmm d, yyyy")&" is too far back to appear",IF($F28>StartDate+730,"! "&TEXT($F28,"mmm d, yyyy")&" is years away — check it",IF($F28>StartDate+90,"beyond the 13-week window","")))))))))
A29: 25 | K29: =IF($B29="","",IF($H29<>"Yes","",IF(OR($D29="",$D29=0),"! No amount — this will project as $0",IF($F29="","! No next due date",IF(NOT(ISNUMBER($F29)),"! Next due date is not a date — type it as 8/21/2026",IF($E29="","! No frequency chosen",IF($F29<StartDate-90,"! "&TEXT($F29,"mmm d, yyyy")&" is too far back to appear",IF($F29>StartDate+730,"! "&TEXT($F29,"mmm d, yyyy")&" is years away — check it",IF($F29>StartDate+90,"beyond the 13-week window","")))))))))
A30: 26 | K30: =IF($B30="","",IF($H30<>"Yes","",IF(OR($D30="",$D30=0),"! No amount — this will project as $0",IF($F30="","! No next due date",IF(NOT(ISNUMBER($F30)),"! Next due date is not a date — type it as 8/21/2026",IF($E30="","! No frequency chosen",IF($F30<StartDate-90,"! "&TEXT($F30,"mmm d, yyyy")&" is too far back to appear",IF($F30>StartDate+730,"! "&TEXT($F30,"mmm d, yyyy")&" is years away — check it",IF($F30>StartDate+90,"beyond the 13-week window","")))))))))
A31: 27 | K31: =IF($B31="","",IF($H31<>"Yes","",IF(OR($D31="",$D31=0),"! No amount — this will project as $0",IF($F31="","! No next due date",IF(NOT(ISNUMBER($F31)),"! Next due date is not a date — type it as 8/21/2026",IF($E31="","! No frequency chosen",IF($F31<StartDate-90,"! "&TEXT($F31,"mmm d, yyyy")&" is too far back to appear",IF($F31>StartDate+730,"! "&TEXT($F31,"mmm d, yyyy")&" is years away — check it",IF($F31>StartDate+90,"beyond the 13-week window","")))))))))
A32: 28 | K32: =IF($B32="","",IF($H32<>"Yes","",IF(OR($D32="",$D32=0),"! No amount — this will project as $0",IF($F32="","! No next due date",IF(NOT(ISNUMBER($F32)),"! Next due date is not a date — type it as 8/21/2026",IF($E32="","! No frequency chosen",IF($F32<StartDate-90,"! "&TEXT($F32,"mmm d, yyyy")&" is too far back to appear",IF($F32>StartDate+730,"! "&TEXT($F32,"mmm d, yyyy")&" is years away — check it",IF($F32>StartDate+90,"beyond the 13-week window","")))))))))
A33: 29 | K33: =IF($B33="","",IF($H33<>"Yes","",IF(OR($D33="",$D33=0),"! No amount — this will project as $0",IF($F33="","! No next due date",IF(NOT(ISNUMBER($F33)),"! Next due date is not a date — type it as 8/21/2026",IF($E33="","! No frequency chosen",IF($F33<StartDate-90,"! "&TEXT($F33,"mmm d, yyyy")&" is too far back to appear",IF($F33>StartDate+730,"! "&TEXT($F33,"mmm d, yyyy")&" is years away — check it",IF($F33>StartDate+90,"beyond the 13-week window","")))))))))
A34: 30 | K34: =IF($B34="","",IF($H34<>"Yes","",IF(OR($D34="",$D34=0),"! No amount — this will project as $0",IF($F34="","! No next due date",IF(NOT(ISNUMBER($F34)),"! Next due date is not a date — type it as 8/21/2026",IF($E34="","! No frequency chosen",IF($F34<StartDate-90,"! "&TEXT($F34,"mmm d, yyyy")&" is too far back to appear",IF($F34>StartDate+730,"! "&TEXT($F34,"mmm d, yyyy")&" is years away — check it",IF($F34>StartDate+90,"beyond the 13-week window","")))))))))
B36: Next Due Date = the next occurrence you have NOT paid yet. A date already in the past is fine — it appears in Week 1 marked PAST DUE and stays there until you deal with it. Only move a date forward once the money has actually moved. Set Active to No to park a transaction without deleting it.
B37: Weekend Rule shifts a due date that lands on a Saturday or Sunday: Move Before = the Friday, Move After = the Monday, None = leave it alone.
B38: Source: transcribed from the user's budget-app Recurring screenshots, August 2026.

Sheet Summary
B1: 13-WEEK SURVIVAL SUMMARY
B2: Every figure here is pulled live from the Cash Flow tab.
B3: AT A GLANCE
B4: Cash available now | D4: =BeginningBalance+SUM($N$13:$N$25)-SUM($O$13:$O$25) -> 168.67 | F4: Minimum cash cushion | H4: =MinCushion -> 200 | N4: =IF(COUNT(Schedule!$N$4:$N$483)=0,"",MIN(Schedule!$N$4:$N$483)) -> 4626000005
B5: Lowest before then | D5: =IF($N$4="","",MIN($D$4,MIN($P$13:$P$25))) -> 168.67 | F5: Short of cushion by | H5: =MAX(0,MinCushion-MIN($J$13:$J$25)) -> 629.94 | N5: =IF(COUNT(Schedule!$M$4:$M$483)=0,"",MIN(Schedule!$M$4:$M$483)) -> 4626400244
B6: Lowest in projection | D6: =MIN($J$13:$J$25) -> -429.94 | F6: Periods going negative | H6: =COUNTIF($J$13:$J$25,"<0")&" of 13" -> 11 of 13 | N6: =IF($N$4="","",INT($N$4/100000)) -> 46260
B7: Ending balance | D7: =$I$25 -> -208.68 | F7: Next major bill | H7: =IF($N$5="","none over $100",$N$10&" "&TEXT($N$11,"$#,##0.00")&" on "&TEXT($N$9,"ddd mmm d")) -> Maine Revenue Services (2) $150.00 on Sun Aug 30 | N7: =IF($N$4="","",INDEX(Schedule!$C$4:$C$483,MATCH($N$4,Schedule!$N$4:$N$483,0))) -> Bruno's Restaurant (paycheck)
B8: Next money in | D8: =IF($N$4="","none scheduled",$N$7&" "&TEXT($N$8,"$#,##0.00")&" on "&TEXT($N$6,"ddd mmm d")) -> Bruno's Restaurant (paycheck) $90.00 on Wed Aug 26 | F8: Needs attention | H8: =IF(COUNTIF(Recurring!$K$5:$K$34,"!*")=0,"All recurring items complete","! "&COUNTIF(Recurring!$K$5:$K$34,"!*")&" recurring item(s) need attention — see the Recurring tab") -> All recurring items complete | N8: =IF($N$4="","",INDEX(Schedule!$E$4:$E$483,MATCH($N$4,Schedule!$N$4:$N$483,0))) -> 90
N9: =IF($N$5="","",INT($N$5/100000)) -> 46264
B10: Cash available now is the beginning balance plus every transaction dated today or earlier. Lowest before then is the worst point between now and the next money in. Everyday Spending includes the top-up for weeks not yet logged. | N10: =IF($N$5="","",INDEX(Schedule!$C$4:$C$483,MATCH($N$5,Schedule!$M$4:$M$483,0))) -> Maine Revenue Services (2)
N11: =IF($N$5="","",INDEX(Schedule!$E$4:$E$483,MATCH($N$5,Schedule!$M$4:$M$483,0))) -> 150
B12: Week | C12: Week Beginning | D12: Money In | E12: Recurring Bills | F12: Everyday Spending | G12: Weekly Surplus | H12: Carried Forward | I12: Left at Week End | J12: Lowest In Week | K12: On | L12: Status | M12: shortfall key | Q12: Zero | R12: Cushion
B13: 1 | C13: ='Cash Flow'!$E$6+0 -> 46249 | D13: =SUM('Cash Flow'!$G$15:$G$65) -> 950.99 | E13: =SUM('Cash Flow'!$H$15:$H$24) -> 45 | F13: =SUM('Cash Flow'!$H$26:$H$65) -> 621.74 | G13: =$D13-$E13-$F13 -> 284.25 | H13: ='Cash Flow'!$I$13 -> 228.41 | I13: ='Cash Flow'!$I$66 -> 512.66 | J13: =MIN('Cash Flow'!$I$15:$I$65) -> -262.64 | K13: =IFERROR(INDEX('Cash Flow'!$C$15:$C$65,MATCH(MIN('Cash Flow'!$I$15:$I$65),'Cash Flow'!$I$15:$I$65,0)),"") -> 46254 | L13: =IF($J13<0,"SHORTFALL",IF($J13<'Cash Flow'!$E$7,"TIGHT","OK")) -> SHORTFALL | M13: =IF($J13<0,$B13,999) -> 1 | N13: =SUMIFS('Cash Flow'!$G$15:$G$65,'Cash Flow'!$C$15:$C$65,"<="&TODAY()) -> 950.99 | O13: =SUMIFS('Cash Flow'!$H$15:$H$65,'Cash Flow'!$C$15:$C$65,"<="&TODAY()) -> 666.74 | P13: =IF($N$4="","",IF(COUNTIFS('Cash Flow'!$C$15:$C$65,">="&TODAY(),'Cash Flow'!$C$15:$C$65,"<="&$N$6)=0,"",_xlfn.MINIFS('Cash Flow'!$I$15:$I$65,'Cash Flow'!$C$15:$C$65,">="&TODAY(),'Cash Flow'!$C$15:$C$65,"<="&$N$6))) | Q13: 0 | R13: =MinCushion -> 200
B14: 2 | C14: ='Cash Flow'!$E$6+7 -> 46256 | D14: =SUM('Cash Flow'!$G$70:$G$120) -> 835 | E14: =SUM('Cash Flow'!$H$70:$H$79) -> 313.7 | F14: =SUM('Cash Flow'!$H$81:$H$120) -> 400 | G14: =$D14-$E14-$F14 -> 121.3 | H14: ='Cash Flow'!$I$68 -> 512.66 | I14: ='Cash Flow'!$I$121 -> 633.96 | J14: =MIN('Cash Flow'!$I$70:$I$120) -> 168.67 | K14: =IFERROR(INDEX('Cash Flow'!$C$70:$C$120,MATCH(MIN('Cash Flow'!$I$70:$I$120),'Cash Flow'!$I$70:$I$120,0)),"") -> 46256 | L14: =IF($J14<0,"SHORTFALL",IF($J14<'Cash Flow'!$E$7,"TIGHT","OK")) -> TIGHT | M14: =IF($J14<0,$B14,999) -> 999 | N14: =SUMIFS('Cash Flow'!$G$70:$G$120,'Cash Flow'!$C$70:$C$120,"<="&TODAY()) -> 0 | O14: =SUMIFS('Cash Flow'!$H$70:$H$120,'Cash Flow'!$C$70:$C$120,"<="&TODAY()) -> 343.99 | P14: =IF($N$4="","",IF(COUNTIFS('Cash Flow'!$C$70:$C$120,">="&TODAY(),'Cash Flow'!$C$70:$C$120,"<="&$N$6)=0,"",_xlfn.MINIFS('Cash Flow'!$I$70:$I$120,'Cash Flow'!$C$70:$C$120,">="&TODAY(),'Cash Flow'!$C$70:$C$120,"<="&$N$6))) -> 258.67 | Q14: 0 | R14: =MinCushion -> 200
B15: 3 | C15: ='Cash Flow'!$E$6+14 -> 46263 | D15: =SUM('Cash Flow'!$G$125:$G$175) -> 835 | E15: =SUM('Cash Flow'!$H$125:$H$134) -> 664.47 | F15: =SUM('Cash Flow'!$H$136:$H$175) -> 400 | G15: =$D15-$E15-$F15 -> -229.47 | H15: ='Cash Flow'!$I$123 -> 633.96 | I15: ='Cash Flow'!$I$176 -> 404.49 | J15: =MIN('Cash Flow'!$I$125:$I$175) -> -9.41 | K15: =IFERROR(INDEX('Cash Flow'!$C$125:$C$175,MATCH(MIN('Cash Flow'!$I$125:$I$175),'Cash Flow'!$I$125:$I$175,0)),"") -> 46265 | L15: =IF($J15<0,"SHORTFALL",IF($J15<'Cash Flow'!$E$7,"TIGHT","OK")) -> SHORTFALL | M15: =IF($J15<0,$B15,999) -> 3 | N15: =SUMIFS('Cash Flow'!$G$125:$G$175,'Cash Flow'!$C$125:$C$175,"<="&TODAY()) -> 0 | O15: =SUMIFS('Cash Flow'!$H$125:$H$175,'Cash Flow'!$C$125:$C$175,"<="&TODAY()) -> 0 | P15: =IF($N$4="","",IF(COUNTIFS('Cash Flow'!$C$125:$C$175,">="&TODAY(),'Cash Flow'!$C$125:$C$175,"<="&$N$6)=0,"",_xlfn.MINIFS('Cash Flow'!$I$125:$I$175,'Cash Flow'!$C$125:$C$175,">="&TODAY(),'Cash Flow'!$C$125:$C$175,"<="&$N$6))) | Q15: 0 | R15: =MinCushion -> 200
B16: 4 | C16: ='Cash Flow'!$E$6+21 -> 46270 | D16: =SUM('Cash Flow'!$G$180:$G$230) -> 835 | E16: =SUM('Cash Flow'!$H$180:$H$189) -> 718.68 | F16: =SUM('Cash Flow'!$H$191:$H$230) -> 400 | G16: =$D16-$E16-$F16 -> -283.68 | H16: ='Cash Flow'!$I$178 -> 404.49 | I16: ='Cash Flow'!$I$231 -> 120.81 | J16: =MIN('Cash Flow'!$I$180:$I$230) -> -314.19 | K16: =IFERROR(INDEX('Cash Flow'!$C$180:$C$230,MATCH(MIN('Cash Flow'!$I$180:$I$230),'Cash Flow'!$I$180:$I$230,0)),"") -> 46273 | L16: =IF($J16<0,"SHORTFALL",IF($J16<'Cash Flow'!$E$7,"TIGHT","OK")) -> SHORTFALL | M16: =IF($J16<0,$B16,999) -> 4 | N16: =SUMIFS('Cash Flow'!$G$180:$G$230,'Cash Flow'!$C$180:$C$230,"<="&TODAY()) -> 0 | O16: =SUMIFS('Cash Flow'!$H$180:$H$230,'Cash Flow'!$C$180:$C$230,"<="&TODAY()) -> 0 | P16: =IF($N$4="","",IF(COUNTIFS('Cash Flow'!$C$180:$C$230,">="&TODAY(),'Cash Flow'!$C$180:$C$230,"<="&$N$6)=0,"",_xlfn.MINIFS('Cash Flow'!$I$180:$I$230,'Cash Flow'!$C$180:$C$230,">="&TODAY(),'Cash Flow'!$C$180:$C$230,"<="&$N$6))) | Q16: 0 | R16: =MinCushion -> 200
B17: 5 | C17: ='Cash Flow'!$E$6+28 -> 46277 | D17: =SUM('Cash Flow'!$G$235:$G$285) -> 835 | E17: =SUM('Cash Flow'!$H$235:$H$244) -> 397.99 | F17: =SUM('Cash Flow'!$H$246:$H$285) -> 400 | G17: =$D17-$E17-$F17 -> 37.01 | H17: ='Cash Flow'!$I$233 -> 120.81 | I17: ='Cash Flow'!$I$286 -> 157.82 | J17: =MIN('Cash Flow'!$I$235:$I$285) -> -232.18 | K17: =IFERROR(INDEX('Cash Flow'!$C$235:$C$285,MATCH(MIN('Cash Flow'!$I$235:$I$285),'Cash Flow'!$I$235:$I$285,0)),"") -> 46280 | L17: =IF($J17<0,"SHORTFALL",IF($J17<'Cash Flow'!$E$7,"TIGHT","OK")) -> SHORTFALL | M17: =IF($J17<0,$B17,999) -> 5 | N17: =SUMIFS('Cash Flow'!$G$235:$G$285,'Cash Flow'!$C$235:$C$285,"<="&TODAY()) -> 0 | O17: =SUMIFS('Cash Flow'!$H$235:$H$285,'Cash Flow'!$C$235:$C$285,"<="&TODAY()) -> 0 | P17: =IF($N$4="","",IF(COUNTIFS('Cash Flow'!$C$235:$C$285,">="&TODAY(),'Cash Flow'!$C$235:$C$285,"<="&$N$6)=0,"",_xlfn.MINIFS('Cash Flow'!$I$235:$I$285,'Cash Flow'!$C$235:$C$285,">="&TODAY(),'Cash Flow'!$C$235:$C$285,"<="&$N$6))) | Q17: 0 | R17: =MinCushion -> 200
B18: 6 | C18: ='Cash Flow'!$E$6+35 -> 46284 | D18: =SUM('Cash Flow'!$G$290:$G$340) -> 835 | E18: =SUM('Cash Flow'!$H$290:$H$299) -> 184.8 | F18: =SUM('Cash Flow'!$H$301:$H$340) -> 400 | G18: =$D18-$E18-$F18 -> 250.2 | H18: ='Cash Flow'!$I$288 -> 157.82 | I18: ='Cash Flow'!$I$341 -> 408.02 | J18: =MIN('Cash Flow'!$I$290:$I$340) -> -26.98 | K18: =IFERROR(INDEX('Cash Flow'!$C$290:$C$340,MATCH(MIN('Cash Flow'!$I$290:$I$340),'Cash Flow'!$I$290:$I$340,0)),"") -> 46287 | L18: =IF($J18<0,"SHORTFALL",IF($J18<'Cash Flow'!$E$7,"TIGHT","OK")) -> SHORTFALL | M18: =IF($J18<0,$B18,999) -> 6 | N18: =SUMIFS('Cash Flow'!$G$290:$G$340,'Cash Flow'!$C$290:$C$340,"<="&TODAY()) -> 0 | O18: =SUMIFS('Cash Flow'!$H$290:$H$340,'Cash Flow'!$C$290:$C$340,"<="&TODAY()) -> 0 | P18: =IF($N$4="","",IF(COUNTIFS('Cash Flow'!$C$290:$C$340,">="&TODAY(),'Cash Flow'!$C$290:$C$340,"<="&$N$6)=0,"",_xlfn.MINIFS('Cash Flow'!$I$290:$I$340,'Cash Flow'!$C$290:$C$340,">="&TODAY(),'Cash Flow'!$C$290:$C$340,"<="&$N$6))) | Q18: 0 | R18: =MinCushion -> 200
B19: 7 | C19: ='Cash Flow'!$E$6+42 -> 46291 | D19: =SUM('Cash Flow'!$G$345:$G$395) -> 835 | E19: =SUM('Cash Flow'!$H$345:$H$354) -> 643.37 | F19: =SUM('Cash Flow'!$H$356:$H$395) -> 400 | G19: =$D19-$E19-$F19 -> -208.37 | H19: ='Cash Flow'!$I$343 -> 408.02 | I19: ='Cash Flow'!$I$396 -> 199.65 | J19: =MIN('Cash Flow'!$I$345:$I$395) -> -145.35 | K19: =IFERROR(INDEX('Cash Flow'!$C$345:$C$395,MATCH(MIN('Cash Flow'!$I$345:$I$395),'Cash Flow'!$I$345:$I$395,0)),"") -> 46295 | L19: =IF($J19<0,"SHORTFALL",IF($J19<'Cash Flow'!$E$7,"TIGHT","OK")) -> SHORTFALL | M19: =IF($J19<0,$B19,999) -> 7 | N19: =SUMIFS('Cash Flow'!$G$345:$G$395,'Cash Flow'!$C$345:$C$395,"<="&TODAY()) -> 0 | O19: =SUMIFS('Cash Flow'!$H$345:$H$395,'Cash Flow'!$C$345:$C$395,"<="&TODAY()) -> 0 | P19: =IF($N$4="","",IF(COUNTIFS('Cash Flow'!$C$345:$C$395,">="&TODAY(),'Cash Flow'!$C$345:$C$395,"<="&$N$6)=0,"",_xlfn.MINIFS('Cash Flow'!$I$345:$I$395,'Cash Flow'!$C$345:$C$395,">="&TODAY(),'Cash Flow'!$C$345:$C$395,"<="&$N$6))) | Q19: 0 | R19: =MinCushion -> 200
B20: 8 | C20: ='Cash Flow'!$E$6+49 -> 46298 | D20: =SUM('Cash Flow'!$G$400:$G$450) -> 835 | E20: =SUM('Cash Flow'!$H$400:$H$409) -> 719.59 | F20: =SUM('Cash Flow'!$H$411:$H$450) -> 400 | G20: =$D20-$E20-$F20 -> -284.59 | H20: ='Cash Flow'!$I$398 -> 199.65 | I20: ='Cash Flow'!$I$451 -> -84.94 | J20: =MIN('Cash Flow'!$I$400:$I$450) -> -429.94 | K20: =IFERROR(INDEX('Cash Flow'!$C$400:$C$450,MATCH(MIN('Cash Flow'!$I$400:$I$450),'Cash Flow'!$I$400:$I$450,0)),"") -> 46303 | L20: =IF($J20<0,"SHORTFALL",IF($J20<'Cash Flow'!$E$7,"TIGHT","OK")) -> SHORTFALL | M20: =IF($J20<0,$B20,999) -> 8 | N20: =SUMIFS('Cash Flow'!$G$400:$G$450,'Cash Flow'!$C$400:$C$450,"<="&TODAY()) -> 0 | O20: =SUMIFS('Cash Flow'!$H$400:$H$450,'Cash Flow'!$C$400:$C$450,"<="&TODAY()) -> 0 | P20: =IF($N$4="","",IF(COUNTIFS('Cash Flow'!$C$400:$C$450,">="&TODAY(),'Cash Flow'!$C$400:$C$450,"<="&$N$6)=0,"",_xlfn.MINIFS('Cash Flow'!$I$400:$I$450,'Cash Flow'!$C$400:$C$450,">="&TODAY(),'Cash Flow'!$C$400:$C$450,"<="&$N$6))) | Q20: 0 | R20: =MinCushion -> 200
B21: 9 | C21: ='Cash Flow'!$E$6+56 -> 46305 | D21: =SUM('Cash Flow'!$G$455:$G$505) -> 835 | E21: =SUM('Cash Flow'!$H$455:$H$464) -> 397.99 | F21: =SUM('Cash Flow'!$H$466:$H$505) -> 400 | G21: =$D21-$E21-$F21 -> 37.01 | H21: ='Cash Flow'!$I$453 -> -84.94 | I21: ='Cash Flow'!$I$506 -> -47.93 | J21: =MIN('Cash Flow'!$I$455:$I$505) -> -347.93 | K21: =IFERROR(INDEX('Cash Flow'!$C$455:$C$505,MATCH(MIN('Cash Flow'!$I$455:$I$505),'Cash Flow'!$I$455:$I$505,0)),"") -> 46310 | L21: =IF($J21<0,"SHORTFALL",IF($J21<'Cash Flow'!$E$7,"TIGHT","OK")) -> SHORTFALL | M21: =IF($J21<0,$B21,999) -> 9 | N21: =SUMIFS('Cash Flow'!$G$455:$G$505,'Cash Flow'!$C$455:$C$505,"<="&TODAY()) -> 0 | O21: =SUMIFS('Cash Flow'!$H$455:$H$505,'Cash Flow'!$C$455:$C$505,"<="&TODAY()) -> 0 | P21: =IF($N$4="","",IF(COUNTIFS('Cash Flow'!$C$455:$C$505,">="&TODAY(),'Cash Flow'!$C$455:$C$505,"<="&$N$6)=0,"",_xlfn.MINIFS('Cash Flow'!$I$455:$I$505,'Cash Flow'!$C$455:$C$505,">="&TODAY(),'Cash Flow'!$C$455:$C$505,"<="&$N$6))) | Q21: 0 | R21: =MinCushion -> 200
B22: 10 | C22: ='Cash Flow'!$E$6+63 -> 46312 | D22: =SUM('Cash Flow'!$G$510:$G$560) -> 835 | E22: =SUM('Cash Flow'!$H$510:$H$519) -> 184.8 | F22: =SUM('Cash Flow'!$H$521:$H$560) -> 400 | G22: =$D22-$E22-$F22 -> 250.2 | H22: ='Cash Flow'!$I$508 -> -47.93 | I22: ='Cash Flow'!$I$561 -> 202.27 | J22: =MIN('Cash Flow'!$I$510:$I$560) -> -142.73 | K22: =IFERROR(INDEX('Cash Flow'!$C$510:$C$560,MATCH(MIN('Cash Flow'!$I$510:$I$560),'Cash Flow'!$I$510:$I$560,0)),"") -> 46317 | L22: =IF($J22<0,"SHORTFALL",IF($J22<'Cash Flow'!$E$7,"TIGHT","OK")) -> SHORTFALL | M22: =IF($J22<0,$B22,999) -> 10 | N22: =SUMIFS('Cash Flow'!$G$510:$G$560,'Cash Flow'!$C$510:$C$560,"<="&TODAY()) -> 0 | O22: =SUMIFS('Cash Flow'!$H$510:$H$560,'Cash Flow'!$C$510:$C$560,"<="&TODAY()) -> 0 | P22: =IF($N$4="","",IF(COUNTIFS('Cash Flow'!$C$510:$C$560,">="&TODAY(),'Cash Flow'!$C$510:$C$560,"<="&$N$6)=0,"",_xlfn.MINIFS('Cash Flow'!$I$510:$I$560,'Cash Flow'!$C$510:$C$560,">="&TODAY(),'Cash Flow'!$C$510:$C$560,"<="&$N$6))) | Q22: 0 | R22: =MinCushion -> 200
B23: 11 | C23: ='Cash Flow'!$E$6+70 -> 46319 | D23: =SUM('Cash Flow'!$G$565:$G$615) -> 835 | E23: =SUM('Cash Flow'!$H$565:$H$574) -> 500 | F23: =SUM('Cash Flow'!$H$576:$H$615) -> 400 | G23: =$D23-$E23-$F23 -> -65 | H23: ='Cash Flow'!$I$563 -> 202.27 | I23: ='Cash Flow'!$I$616 -> 137.27 | J23: =MIN('Cash Flow'!$I$565:$I$615) -> 137.27 | K23: =IFERROR(INDEX('Cash Flow'!$C$565:$C$615,MATCH(MIN('Cash Flow'!$I$565:$I$615),'Cash Flow'!$I$565:$I$615,0)),"") -> 46325 | L23: =IF($J23<0,"SHORTFALL",IF($J23<'Cash Flow'!$E$7,"TIGHT","OK")) -> TIGHT | M23: =IF($J23<0,$B23,999) -> 999 | N23: =SUMIFS('Cash Flow'!$G$565:$G$615,'Cash Flow'!$C$565:$C$615,"<="&TODAY()) -> 0 | O23: =SUMIFS('Cash Flow'!$H$565:$H$615,'Cash Flow'!$C$565:$C$615,"<="&TODAY()) -> 0 | P23: =IF($N$4="","",IF(COUNTIFS('Cash Flow'!$C$565:$C$615,">="&TODAY(),'Cash Flow'!$C$565:$C$615,"<="&$N$6)=0,"",_xlfn.MINIFS('Cash Flow'!$I$565:$I$615,'Cash Flow'!$C$565:$C$615,">="&TODAY(),'Cash Flow'!$C$565:$C$615,"<="&$N$6))) | Q23: 0 | R23: =MinCushion -> 200
B24: 12 | C24: ='Cash Flow'!$E$6+77 -> 46326 | D24: =SUM('Cash Flow'!$G$620:$G$670) -> 835 | E24: =SUM('Cash Flow'!$H$620:$H$629) -> 194.47 | F24: =SUM('Cash Flow'!$H$631:$H$670) -> 400 | G24: =$D24-$E24-$F24 -> 240.53 | H24: ='Cash Flow'!$I$618 -> 137.27 | I24: ='Cash Flow'!$I$671 -> 377.8 | J24: =MIN('Cash Flow'!$I$620:$I$670) -> -6.1 | K24: =IFERROR(INDEX('Cash Flow'!$C$620:$C$670,MATCH(MIN('Cash Flow'!$I$620:$I$670),'Cash Flow'!$I$620:$I$670,0)),"") -> 46326 | L24: =IF($J24<0,"SHORTFALL",IF($J24<'Cash Flow'!$E$7,"TIGHT","OK")) -> SHORTFALL | M24: =IF($J24<0,$B24,999) -> 12 | N24: =SUMIFS('Cash Flow'!$G$620:$G$670,'Cash Flow'!$C$620:$C$670,"<="&TODAY()) -> 0 | O24: =SUMIFS('Cash Flow'!$H$620:$H$670,'Cash Flow'!$C$620:$C$670,"<="&TODAY()) -> 0 | P24: =IF($N$4="","",IF(COUNTIFS('Cash Flow'!$C$620:$C$670,">="&TODAY(),'Cash Flow'!$C$620:$C$670,"<="&$N$6)=0,"",_xlfn.MINIFS('Cash Flow'!$I$620:$I$670,'Cash Flow'!$C$620:$C$670,">="&TODAY(),'Cash Flow'!$C$620:$C$670,"<="&$N$6))) | Q24: 0 | R24: =MinCushion -> 200
B25: 13 | C25: ='Cash Flow'!$E$6+84 -> 46333 | D25: =SUM('Cash Flow'!$G$675:$G$725) -> 835 | E25: =SUM('Cash Flow'!$H$675:$H$684) -> 1021.48 | F25: =SUM('Cash Flow'!$H$686:$H$725) -> 400 | G25: =$D25-$E25-$F25 -> -586.48 | H25: ='Cash Flow'!$I$673 -> 377.8 | I25: ='Cash Flow'!$I$726 -> -208.68 | J25: =MIN('Cash Flow'!$I$675:$I$725) -> -290.69 | K25: =IFERROR(INDEX('Cash Flow'!$C$675:$C$725,MATCH(MIN('Cash Flow'!$I$675:$I$725),'Cash Flow'!$I$675:$I$725,0)),"") -> 46334 | L25: =IF($J25<0,"SHORTFALL",IF($J25<'Cash Flow'!$E$7,"TIGHT","OK")) -> SHORTFALL | M25: =IF($J25<0,$B25,999) -> 13 | N25: =SUMIFS('Cash Flow'!$G$675:$G$725,'Cash Flow'!$C$675:$C$725,"<="&TODAY()) -> 0 | O25: =SUMIFS('Cash Flow'!$H$675:$H$725,'Cash Flow'!$C$675:$C$725,"<="&TODAY()) -> 0 | P25: =IF($N$4="","",IF(COUNTIFS('Cash Flow'!$C$675:$C$725,">="&TODAY(),'Cash Flow'!$C$675:$C$725,"<="&$N$6)=0,"",_xlfn.MINIFS('Cash Flow'!$I$675:$I$725,'Cash Flow'!$C$675:$C$725,">="&TODAY(),'Cash Flow'!$C$675:$C$725,"<="&$N$6))) | Q25: 0 | R25: =MinCushion -> 200
B26: TOTAL | D26: =SUM($D$13:$D$25) -> 10970.99 | E26: =SUM($E$13:$E$25) -> 5986.34 | F26: =SUM($F$13:$F$25) -> 5421.74 | G26: =SUM($G$13:$G$25) -> -437.09 | H26: =$H$13 -> 228.41 | I26: =$I$25 -> -208.68 | J26: =MIN($J$13:$J$25) -> -429.94
B28: Weekly Surplus is the week standing on its own — money in less both kinds of spending, with nothing carried in. Carried Forward is what last week left you. Add the two and you get Left at Week End. A week can close on a healthy figure while its own surplus is negative, which is why they are separate. Lowest In Week is the worst moment inside the week, and Status is judged on that rather than on the closing figure. Everyday Spending includes the top-up to your expected weekly figure for any week you have not logged yet, so untouched weeks are not forecast at zero.

Sheet Week Cards
B2: THE WEEKS AHEAD
B3: Red banner: the week dips below zero. Amber: it stays up but lands under your cushion.
B4: Nothing here is typed in. Edit elsewhere and these follow.
B6: ="WEEK "&Summary!$B13&" "&TEXT(Summary!$C13,"mmm d")&" - "&TEXT(Summary!$C13+6,"mmm d") -> WEEK 1 Aug 15 - Aug 21 | F6: ="WEEK "&Summary!$B14&" "&TEXT(Summary!$C14,"mmm d")&" - "&TEXT(Summary!$C14+6,"mmm d") -> WEEK 2 Aug 22 - Aug 28 | J6: ="WEEK "&Summary!$B15&" "&TEXT(Summary!$C15,"mmm d")&" - "&TEXT(Summary!$C15+6,"mmm d") -> WEEK 3 Aug 29 - Sep 4
B7: Starts with | D7: =Summary!$H13 -> 228.41 | F7: Starts with | H7: =Summary!$H14 -> 512.66 | J7: Starts with | L7: =Summary!$H15 -> 633.96
B8: SCHEDULED THIS WEEK | F8: SCHEDULED THIS WEEK | J8: SCHEDULED THIS WEEK
B9: =IF('Cash Flow'!$B15="","",'Cash Flow'!$C15) -> 46250 | C9: =IF('Cash Flow'!$B15="","",'Cash Flow'!$B15) -> Maine Revenue Services | D9: =IF('Cash Flow'!$B15="","",IF('Cash Flow'!$G15<>"",'Cash Flow'!$G15,-'Cash Flow'!$H15)) -> -45 | F9: =IF('Cash Flow'!$B70="","",'Cash Flow'!$C70) -> 46256 | G9: =IF('Cash Flow'!$B70="","",'Cash Flow'!$B70) -> Microsoft | H9: =IF('Cash Flow'!$B70="","",IF('Cash Flow'!$G70<>"",'Cash Flow'!$G70,-'Cash Flow'!$H70)) -> -13.7 | J9: =IF('Cash Flow'!$B125="","",'Cash Flow'!$C125) -> 46264 | K9: =IF('Cash Flow'!$B125="","",'Cash Flow'!$B125) -> Maine Revenue Services (2) | L9: =IF('Cash Flow'!$B125="","",IF('Cash Flow'!$G125<>"",'Cash Flow'!$G125,-'Cash Flow'!$H125)) -> -150
B10: =IF('Cash Flow'!$B16="","",'Cash Flow'!$C16) -> 46253 | C10: =IF('Cash Flow'!$B16="","",'Cash Flow'!$B16) -> Bruno's Restaurant (paycheck) | D10: =IF('Cash Flow'!$B16="","",IF('Cash Flow'!$G16<>"",'Cash Flow'!$G16,-'Cash Flow'!$H16)) -> 148.34 | F10: =IF('Cash Flow'!$B71="","",'Cash Flow'!$C71) -> 46256 | G10: =IF('Cash Flow'!$B71="","",'Cash Flow'!$B71) -> School clothes (back to school) | H10: =IF('Cash Flow'!$B71="","",IF('Cash Flow'!$G71<>"",'Cash Flow'!$G71,-'Cash Flow'!$H71)) -> -300 | J10: =IF('Cash Flow'!$B126="","",'Cash Flow'!$C126) -> 46265 | K10: =IF('Cash Flow'!$B126="","",'Cash Flow'!$B126) -> Patrick Rombalski (rent) | L10: =IF('Cash Flow'!$B126="","",IF('Cash Flow'!$G126<>"",'Cash Flow'!$G126,-'Cash Flow'!$H126)) -> -350
B11: =IF('Cash Flow'!$B17="","",'Cash Flow'!$C17) -> 46255 | C11: =IF('Cash Flow'!$B17="","",'Cash Flow'!$B17) -> Compunnel Software (paycheck) | D11: =IF('Cash Flow'!$B17="","",IF('Cash Flow'!$G17<>"",'Cash Flow'!$G17,-'Cash Flow'!$H17)) -> 802.65 | F11: =IF('Cash Flow'!$B72="","",'Cash Flow'!$C72) -> 46260 | G11: =IF('Cash Flow'!$B72="","",'Cash Flow'!$B72) -> Bruno's Restaurant (paycheck) | H11: =IF('Cash Flow'!$B72="","",IF('Cash Flow'!$G72<>"",'Cash Flow'!$G72,-'Cash Flow'!$H72)) -> 90 | J11: =IF('Cash Flow'!$B127="","",'Cash Flow'!$C127) -> 46265 | K11: =IF('Cash Flow'!$B127="","",'Cash Flow'!$B127) -> Progressive Insurance | L11: =IF('Cash Flow'!$B127="","",IF('Cash Flow'!$G127<>"",'Cash Flow'!$G127,-'Cash Flow'!$H127)) -> -143.37
B12: =IF('Cash Flow'!$B18="","",'Cash Flow'!$C18) -> 46255 | C12: =IF('Cash Flow'!$B18="","",'Cash Flow'!$B18) -> Spectrum | D12: =IF('Cash Flow'!$B18="","",IF('Cash Flow'!$G18<>"",'Cash Flow'!$G18,-'Cash Flow'!$H18)) -> 0 | F12: =IF('Cash Flow'!$B73="","",'Cash Flow'!$C73) -> 46262 | G12: =IF('Cash Flow'!$B73="","",'Cash Flow'!$B73) -> Compunnel Software (paycheck) | H12: =IF('Cash Flow'!$B73="","",IF('Cash Flow'!$G73<>"",'Cash Flow'!$G73,-'Cash Flow'!$H73)) -> 745 | J12: =IF('Cash Flow'!$B128="","",'Cash Flow'!$C128) -> 46267 | K12: =IF('Cash Flow'!$B128="","",'Cash Flow'!$B128) -> Bruno's Restaurant (paycheck) | L12: =IF('Cash Flow'!$B128="","",IF('Cash Flow'!$G128<>"",'Cash Flow'!$G128,-'Cash Flow'!$H128)) -> 90
B13: =IF('Cash Flow'!$B19="","",'Cash Flow'!$C19) | C13: =IF('Cash Flow'!$B19="","",'Cash Flow'!$B19) | D13: =IF('Cash Flow'!$B19="","",IF('Cash Flow'!$G19<>"",'Cash Flow'!$G19,-'Cash Flow'!$H19)) | F13: =IF('Cash Flow'!$B74="","",'Cash Flow'!$C74) | G13: =IF('Cash Flow'!$B74="","",'Cash Flow'!$B74) | H13: =IF('Cash Flow'!$B74="","",IF('Cash Flow'!$G74<>"",'Cash Flow'!$G74,-'Cash Flow'!$H74)) | J13: =IF('Cash Flow'!$B129="","",'Cash Flow'!$C129) -> 46269 | K13: =IF('Cash Flow'!$B129="","",'Cash Flow'!$B129) -> Compunnel Software (paycheck) | L13: =IF('Cash Flow'!$B129="","",IF('Cash Flow'!$G129<>"",'Cash Flow'!$G129,-'Cash Flow'!$H129)) -> 745
B14: =IF('Cash Flow'!$B20="","",'Cash Flow'!$C20) | C14: =IF('Cash Flow'!$B20="","",'Cash Flow'!$B20) | D14: =IF('Cash Flow'!$B20="","",IF('Cash Flow'!$G20<>"",'Cash Flow'!$G20,-'Cash Flow'!$H20)) | F14: =IF('Cash Flow'!$B75="","",'Cash Flow'!$C75) | G14: =IF('Cash Flow'!$B75="","",'Cash Flow'!$B75) | H14: =IF('Cash Flow'!$B75="","",IF('Cash Flow'!$G75<>"",'Cash Flow'!$G75,-'Cash Flow'!$H75)) | J14: =IF('Cash Flow'!$B130="","",'Cash Flow'!$C130) -> 46269 | K14: =IF('Cash Flow'!$B130="","",'Cash Flow'!$B130) -> Apple: Claude | L14: =IF('Cash Flow'!$B130="","",IF('Cash Flow'!$G130<>"",'Cash Flow'!$G130,-'Cash Flow'!$H130)) -> -21.1
B15: =IF('Cash Flow'!$B21="","",'Cash Flow'!$C21) | C15: =IF('Cash Flow'!$B21="","",'Cash Flow'!$B21) | D15: =IF('Cash Flow'!$B21="","",IF('Cash Flow'!$G21<>"",'Cash Flow'!$G21,-'Cash Flow'!$H21)) | F15: =IF('Cash Flow'!$B76="","",'Cash Flow'!$C76) | G15: =IF('Cash Flow'!$B76="","",'Cash Flow'!$B76) | H15: =IF('Cash Flow'!$B76="","",IF('Cash Flow'!$G76<>"",'Cash Flow'!$G76,-'Cash Flow'!$H76)) | J15: =IF('Cash Flow'!$B131="","",'Cash Flow'!$C131) | K15: =IF('Cash Flow'!$B131="","",'Cash Flow'!$B131) | L15: =IF('Cash Flow'!$B131="","",IF('Cash Flow'!$G131<>"",'Cash Flow'!$G131,-'Cash Flow'!$H131))
B16: =IF('Cash Flow'!$B22="","",'Cash Flow'!$C22) | C16: =IF('Cash Flow'!$B22="","",'Cash Flow'!$B22) | D16: =IF('Cash Flow'!$B22="","",IF('Cash Flow'!$G22<>"",'Cash Flow'!$G22,-'Cash Flow'!$H22)) | F16: =IF('Cash Flow'!$B77="","",'Cash Flow'!$C77) | G16: =IF('Cash Flow'!$B77="","",'Cash Flow'!$B77) | H16: =IF('Cash Flow'!$B77="","",IF('Cash Flow'!$G77<>"",'Cash Flow'!$G77,-'Cash Flow'!$H77)) | J16: =IF('Cash Flow'!$B132="","",'Cash Flow'!$C132) | K16: =IF('Cash Flow'!$B132="","",'Cash Flow'!$B132) | L16: =IF('Cash Flow'!$B132="","",IF('Cash Flow'!$G132<>"",'Cash Flow'!$G132,-'Cash Flow'!$H132))
B17: =IF('Cash Flow'!$B23="","",'Cash Flow'!$C23) | C17: =IF('Cash Flow'!$B23="","",'Cash Flow'!$B23) | D17: =IF('Cash Flow'!$B23="","",IF('Cash Flow'!$G23<>"",'Cash Flow'!$G23,-'Cash Flow'!$H23)) | F17: =IF('Cash Flow'!$B78="","",'Cash Flow'!$C78) | G17: =IF('Cash Flow'!$B78="","",'Cash Flow'!$B78) | H17: =IF('Cash Flow'!$B78="","",IF('Cash Flow'!$G78<>"",'Cash Flow'!$G78,-'Cash Flow'!$H78)) | J17: =IF('Cash Flow'!$B133="","",'Cash Flow'!$C133) | K17: =IF('Cash Flow'!$B133="","",'Cash Flow'!$B133) | L17: =IF('Cash Flow'!$B133="","",IF('Cash Flow'!$G133<>"",'Cash Flow'!$G133,-'Cash Flow'!$H133))
B18: =IF('Cash Flow'!$B24="","",'Cash Flow'!$C24) | C18: =IF('Cash Flow'!$B24="","",'Cash Flow'!$B24) | D18: =IF('Cash Flow'!$B24="","",IF('Cash Flow'!$G24<>"",'Cash Flow'!$G24,-'Cash Flow'!$H24)) | F18: =IF('Cash Flow'!$B79="","",'Cash Flow'!$C79) | G18: =IF('Cash Flow'!$B79="","",'Cash Flow'!$B79) | H18: =IF('Cash Flow'!$B79="","",IF('Cash Flow'!$G79<>"",'Cash Flow'!$G79,-'Cash Flow'!$H79)) | J18: =IF('Cash Flow'!$B134="","",'Cash Flow'!$C134) | K18: =IF('Cash Flow'!$B134="","",'Cash Flow'!$B134) | L18: =IF('Cash Flow'!$B134="","",IF('Cash Flow'!$G134<>"",'Cash Flow'!$G134,-'Cash Flow'!$H134))
B19: Money in | D19: =Summary!$D13 -> 950.99 | F19: Money in | H19: =Summary!$D14 -> 835 | J19: Money in | L19: =Summary!$D15 -> 835
B20: Bills | D20: =-Summary!$E13 -> -45 | F20: Bills | H20: =-Summary!$E14 -> -313.7 | J20: Bills | L20: =-Summary!$E15 -> -664.47
B21: Everyday spending | D21: =-Summary!$F13 -> -621.74 | F21: Everyday spending | H21: =-Summary!$F14 -> -400 | J21: Everyday spending | L21: =-Summary!$F15 -> -400
B22: Lowest point | C22: =IF(Summary!$K13="","",TEXT(Summary!$K13,"ddd mmm d")) -> Thu Aug 20 | D22: =Summary!$J13 -> -262.64 | F22: Lowest point | G22: =IF(Summary!$K14="","",TEXT(Summary!$K14,"ddd mmm d")) -> Sat Aug 22 | H22: =Summary!$J14 -> 168.67 | J22: Lowest point | K22: =IF(Summary!$K15="","",TEXT(Summary!$K15,"ddd mmm d")) -> Mon Aug 31 | L22: =Summary!$J15 -> -9.41
B23: ENDS WITH | D23: =Summary!$I13 -> 512.66 | F23: ENDS WITH | H23: =Summary!$I14 -> 633.96 | J23: ENDS WITH | L23: =Summary!$I15 -> 404.49
B24: =Summary!$L13 -> SHORTFALL | F24: =Summary!$L14 -> TIGHT | J24: =Summary!$L15 -> SHORTFALL
B28: ="WEEK "&Summary!$B16&" "&TEXT(Summary!$C16,"mmm d")&" - "&TEXT(Summary!$C16+6,"mmm d") -> WEEK 4 Sep 5 - Sep 11 | F28: ="WEEK "&Summary!$B17&" "&TEXT(Summary!$C17,"mmm d")&" - "&TEXT(Summary!$C17+6,"mmm d") -> WEEK 5 Sep 12 - Sep 18 | J28: ="WEEK "&Summary!$B18&" "&TEXT(Summary!$C18,"mmm d")&" - "&TEXT(Summary!$C18+6,"mmm d") -> WEEK 6 Sep 19 - Sep 25
B29: Starts with | D29: =Summary!$H16 -> 404.49 | F29: Starts with | H29: =Summary!$H17 -> 120.81 | J29: Starts with | L29: =Summary!$H18 -> 157.82
B30: SCHEDULED THIS WEEK | F30: SCHEDULED THIS WEEK | J30: SCHEDULED THIS WEEK
B31: =IF('Cash Flow'!$B180="","",'Cash Flow'!$C180) -> 46270 | C31: =IF('Cash Flow'!$B180="","",'Cash Flow'!$B180) -> OpenAI | D31: =IF('Cash Flow'!$B180="","",IF('Cash Flow'!$G180<>"",'Cash Flow'!$G180,-'Cash Flow'!$H180)) -> -20 | F31: =IF('Cash Flow'!$B235="","",'Cash Flow'!$C235) -> 46278 | G31: =IF('Cash Flow'!$B235="","",'Cash Flow'!$B235) -> Apple: iCloud | H31: =IF('Cash Flow'!$B235="","",IF('Cash Flow'!$G235<>"",'Cash Flow'!$G235,-'Cash Flow'!$H235)) -> -2.99 | J31: =IF('Cash Flow'!$B290="","",'Cash Flow'!$C290) -> 46286 | K31: =IF('Cash Flow'!$B290="","",'Cash Flow'!$B290) -> Spectrum | L31: =IF('Cash Flow'!$B290="","",IF('Cash Flow'!$G290<>"",'Cash Flow'!$G290,-'Cash Flow'!$H290)) -> -171.1
B32: =IF('Cash Flow'!$B181="","",'Cash Flow'!$C181) -> 46270 | C32: =IF('Cash Flow'!$B181="","",'Cash Flow'!$B181) -> Obsidian | D32: =IF('Cash Flow'!$B181="","",IF('Cash Flow'!$G181<>"",'Cash Flow'!$G181,-'Cash Flow'!$H181)) -> -10 | F32: =IF('Cash Flow'!$B236="","",'Cash Flow'!$C236) -> 46280 | G32: =IF('Cash Flow'!$B236="","",'Cash Flow'!$B236) -> Patrick Rombalski (rent) | H32: =IF('Cash Flow'!$B236="","",IF('Cash Flow'!$G236<>"",'Cash Flow'!$G236,-'Cash Flow'!$H236)) -> -350 | J32: =IF('Cash Flow'!$B291="","",'Cash Flow'!$C291) -> 46287 | K32: =IF('Cash Flow'!$B291="","",'Cash Flow'!$B291) -> Microsoft | L32: =IF('Cash Flow'!$B291="","",IF('Cash Flow'!$G291<>"",'Cash Flow'!$G291,-'Cash Flow'!$H291)) -> -13.7
B33: =IF('Cash Flow'!$B182="","",'Cash Flow'!$C182) -> 46272 | C33: =IF('Cash Flow'!$B182="","",'Cash Flow'!$B182) -> Google One | D33: =IF('Cash Flow'!$B182="","",IF('Cash Flow'!$G182<>"",'Cash Flow'!$G182,-'Cash Flow'!$H182)) -> -4.99 | F33: =IF('Cash Flow'!$B237="","",'Cash Flow'!$C237) -> 46281 | G33: =IF('Cash Flow'!$B237="","",'Cash Flow'!$B237) -> Bruno's Restaurant (paycheck) | H33: =IF('Cash Flow'!$B237="","",IF('Cash Flow'!$G237<>"",'Cash Flow'!$G237,-'Cash Flow'!$H237)) -> 90 | J33: =IF('Cash Flow'!$B292="","",'Cash Flow'!$C292) -> 46288 | K33: =IF('Cash Flow'!$B292="","",'Cash Flow'!$B292) -> Bruno's Restaurant (paycheck) | L33: =IF('Cash Flow'!$B292="","",IF('Cash Flow'!$G292<>"",'Cash Flow'!$G292,-'Cash Flow'!$H292)) -> 90
B34: =IF('Cash Flow'!$B183="","",'Cash Flow'!$C183) -> 46272 | C34: =IF('Cash Flow'!$B183="","",'Cash Flow'!$B183) -> Upstart (loan) | D34: =IF('Cash Flow'!$B183="","",IF('Cash Flow'!$G183<>"",'Cash Flow'!$G183,-'Cash Flow'!$H183)) -> -500 | F34: =IF('Cash Flow'!$B238="","",'Cash Flow'!$C238) -> 46281 | G34: =IF('Cash Flow'!$B238="","",'Cash Flow'!$B238) -> Maine Revenue Services | H34: =IF('Cash Flow'!$B238="","",IF('Cash Flow'!$G238<>"",'Cash Flow'!$G238,-'Cash Flow'!$H238)) -> -45 | J34: =IF('Cash Flow'!$B293="","",'Cash Flow'!$C293) -> 46290 | K34: =IF('Cash Flow'!$B293="","",'Cash Flow'!$B293) -> Compunnel Software (paycheck) | L34: =IF('Cash Flow'!$B293="","",IF('Cash Flow'!$G293<>"",'Cash Flow'!$G293,-'Cash Flow'!$H293)) -> 745
B35: =IF('Cash Flow'!$B184="","",'Cash Flow'!$C184) -> 46273 | C35: =IF('Cash Flow'!$B184="","",'Cash Flow'!$B184) -> Central Maine Power Co. | D35: =IF('Cash Flow'!$B184="","",IF('Cash Flow'!$G184<>"",'Cash Flow'!$G184,-'Cash Flow'!$H184)) -> -183.69 | F35: =IF('Cash Flow'!$B239="","",'Cash Flow'!$C239) -> 46283 | G35: =IF('Cash Flow'!$B239="","",'Cash Flow'!$B239) -> Compunnel Software (paycheck) | H35: =IF('Cash Flow'!$B239="","",IF('Cash Flow'!$G239<>"",'Cash Flow'!$G239,-'Cash Flow'!$H239)) -> 745 | J35: =IF('Cash Flow'!$B294="","",'Cash Flow'!$C294) | K35: =IF('Cash Flow'!$B294="","",'Cash Flow'!$B294) | L35: =IF('Cash Flow'!$B294="","",IF('Cash Flow'!$G294<>"",'Cash Flow'!$G294,-'Cash Flow'!$H294))
B36: =IF('Cash Flow'!$B185="","",'Cash Flow'!$C185) -> 46274 | C36: =IF('Cash Flow'!$B185="","",'Cash Flow'!$B185) -> Bruno's Restaurant (paycheck) | D36: =IF('Cash Flow'!$B185="","",IF('Cash Flow'!$G185<>"",'Cash Flow'!$G185,-'Cash Flow'!$H185)) -> 90 | F36: =IF('Cash Flow'!$B240="","",'Cash Flow'!$C240) | G36: =IF('Cash Flow'!$B240="","",'Cash Flow'!$B240) | H36: =IF('Cash Flow'!$B240="","",IF('Cash Flow'!$G240<>"",'Cash Flow'!$G240,-'Cash Flow'!$H240)) | J36: =IF('Cash Flow'!$B295="","",'Cash Flow'!$C295) | K36: =IF('Cash Flow'!$B295="","",'Cash Flow'!$B295) | L36: =IF('Cash Flow'!$B295="","",IF('Cash Flow'!$G295<>"",'Cash Flow'!$G295,-'Cash Flow'!$H295))
B37: =IF('Cash Flow'!$B186="","",'Cash Flow'!$C186) -> 46276 | C37: =IF('Cash Flow'!$B186="","",'Cash Flow'!$B186) -> Compunnel Software (paycheck) | D37: =IF('Cash Flow'!$B186="","",IF('Cash Flow'!$G186<>"",'Cash Flow'!$G186,-'Cash Flow'!$H186)) -> 745 | F37: =IF('Cash Flow'!$B241="","",'Cash Flow'!$C241) | G37: =IF('Cash Flow'!$B241="","",'Cash Flow'!$B241) | H37: =IF('Cash Flow'!$B241="","",IF('Cash Flow'!$G241<>"",'Cash Flow'!$G241,-'Cash Flow'!$H241)) | J37: =IF('Cash Flow'!$B296="","",'Cash Flow'!$C296) | K37: =IF('Cash Flow'!$B296="","",'Cash Flow'!$B296) | L37: =IF('Cash Flow'!$B296="","",IF('Cash Flow'!$G296<>"",'Cash Flow'!$G296,-'Cash Flow'!$H296))
B38: =IF('Cash Flow'!$B187="","",'Cash Flow'!$C187) | C38: =IF('Cash Flow'!$B187="","",'Cash Flow'!$B187) | D38: =IF('Cash Flow'!$B187="","",IF('Cash Flow'!$G187<>"",'Cash Flow'!$G187,-'Cash Flow'!$H187)) | F38: =IF('Cash Flow'!$B242="","",'Cash Flow'!$C242) | G38: =IF('Cash Flow'!$B242="","",'Cash Flow'!$B242) | H38: =IF('Cash Flow'!$B242="","",IF('Cash Flow'!$G242<>"",'Cash Flow'!$G242,-'Cash Flow'!$H242)) | J38: =IF('Cash Flow'!$B297="","",'Cash Flow'!$C297) | K38: =IF('Cash Flow'!$B297="","",'Cash Flow'!$B297) | L38: =IF('Cash Flow'!$B297="","",IF('Cash Flow'!$G297<>"",'Cash Flow'!$G297,-'Cash Flow'!$H297))
B39: =IF('Cash Flow'!$B188="","",'Cash Flow'!$C188) | C39: =IF('Cash Flow'!$B188="","",'Cash Flow'!$B188) | D39: =IF('Cash Flow'!$B188="","",IF('Cash Flow'!$G188<>"",'Cash Flow'!$G188,-'Cash Flow'!$H188)) | F39: =IF('Cash Flow'!$B243="","",'Cash Flow'!$C243) | G39: =IF('Cash Flow'!$B243="","",'Cash Flow'!$B243) | H39: =IF('Cash Flow'!$B243="","",IF('Cash Flow'!$G243<>"",'Cash Flow'!$G243,-'Cash Flow'!$H243)) | J39: =IF('Cash Flow'!$B298="","",'Cash Flow'!$C298) | K39: =IF('Cash Flow'!$B298="","",'Cash Flow'!$B298) | L39: =IF('Cash Flow'!$B298="","",IF('Cash Flow'!$G298<>"",'Cash Flow'!$G298,-'Cash Flow'!$H298))
B40: =IF('Cash Flow'!$B189="","",'Cash Flow'!$C189) | C40: =IF('Cash Flow'!$B189="","",'Cash Flow'!$B189) | D40: =IF('Cash Flow'!$B189="","",IF('Cash Flow'!$G189<>"",'Cash Flow'!$G189,-'Cash Flow'!$H189)) | F40: =IF('Cash Flow'!$B244="","",'Cash Flow'!$C244) | G40: =IF('Cash Flow'!$B244="","",'Cash Flow'!$B244) | H40: =IF('Cash Flow'!$B244="","",IF('Cash Flow'!$G244<>"",'Cash Flow'!$G244,-'Cash Flow'!$H244)) | J40: =IF('Cash Flow'!$B299="","",'Cash Flow'!$C299) | K40: =IF('Cash Flow'!$B299="","",'Cash Flow'!$B299) | L40: =IF('Cash Flow'!$B299="","",IF('Cash Flow'!$G299<>"",'Cash Flow'!$G299,-'Cash Flow'!$H299))
B41: Money in | D41: =Summary!$D16 -> 835 | F41: Money in | H41: =Summary!$D17 -> 835 | J41: Money in | L41: =Summary!$D18 -> 835
B42: Bills | D42: =-Summary!$E16 -> -718.68 | F42: Bills | H42: =-Summary!$E17 -> -397.99 | J42: Bills | L42: =-Summary!$E18 -> -184.8
B43: Everyday spending | D43: =-Summary!$F16 -> -400 | F43: Everyday spending | H43: =-Summary!$F17 -> -400 | J43: Everyday spending | L43: =-Summary!$F18 -> -400
B44: Lowest point | C44: =IF(Summary!$K16="","",TEXT(Summary!$K16,"ddd mmm d")) -> Tue Sep 8 | D44: =Summary!$J16 -> -314.19 | F44: Lowest point | G44: =IF(Summary!$K17="","",TEXT(Summary!$K17,"ddd mmm d")) -> Tue Sep 15 | H44: =Summary!$J17 -> -232.18 | J44: Lowest point | K44: =IF(Summary!$K18="","",TEXT(Summary!$K18,"ddd mmm d")) -> Tue Sep 22 | L44: =Summary!$J18 -> -26.98
B45: ENDS WITH | D45: =Summary!$I16 -> 120.81 | F45: ENDS WITH | H45: =Summary!$I17 -> 157.82 | J45: ENDS WITH | L45: =Summary!$I18 -> 408.02
...

Sheet Cash Flow
B1: WEEKLY CASH FLOW SURVIVAL WORKSHEET
B2: Beginning balance -> every scheduled transaction -> what you actually paid -> where you stand at the end of each week.
B4: STEP 1 — SET YOUR STARTING POINT (type in the yellow cells)
B5: Beginning Balance (cash on hand at the start date) | E5: 228.41
B6: Cash Flow Start Date (use a Friday — weeks run Fri to Thu) | E6: 46249 | G6: =IF($E$6="","","Projection runs "&TEXT($E$6,"ddd mmm d")&" to "&TEXT($E$6+90,"ddd mmm d, yyyy")&" · periods are full 7-day weeks beginning "&TEXT($E$6,"dddd")&"s.") -> Projection runs Sat Aug 15 to Fri Nov 13, 2026 · periods are full 7-day weeks beginning Saturdays.
B7: Minimum Cash Cushion (warn me below this) | E7: 200
B8: Expected everyday spending, per week | E8: 400 | G8: Groceries, gas, coffee — what a normal week costs you. Each week is topped up to this until you log more than it.
B9: Today | E9: =TODAY() -> 46258
B10: This sheet projects 13 weeks from the start date. Week 1 begins on the start date.
B11: Money coming in and money going out sit in separate columns and are never added together. A yellow 'Amount Paid' cell means that transaction is due or overdue and still unrecorded. The green transaction cells are safe to type straight over when a date or amount is wrong — the balances keep working. See the Instructions tab.
B12: Blue text on yellow = you type it · ACTUAL = already happened · FORECAST = still expected · everything else is calculated
B13: ="WEEK 1 "&TEXT($E$6+0,"ddd, mmm d")&" through "&TEXT($E$6+0+6,"ddd, mmm d, yyyy") -> WEEK 1 Sat, Aug 15 through Fri, Aug 21, 2026 | G13: Starting balance: | I13: =$E$5 -> 228.41 | N13: =IF(COUNTIF(Schedule!$I$4:$I$483,1)>10,"! "&COUNTIF(Schedule!$I$4:$I$483,1)-10&" more transaction(s) fall in this week than there are rows to show them.","")
B14: Recurring Transaction | C14: Scheduled Date | D14: Type | E14: Scheduled Amount | F14: Amount Paid / Received | G14: MONEY IN | H14: MONEY OUT | I14: Running Balance | J14: Status | K14: Actual / Forecast
B15: =IFERROR(INDEX(Schedule!$C$4:$C$483,MATCH(1001,Schedule!$K$4:$K$483,0)),"") -> Maine Revenue Services | C15: =IF($B15="","",INDEX(Schedule!$G$4:$G$483,MATCH(1001,Schedule!$K$4:$K$483,0))) -> 46250 | D15: =IF($B15="","",INDEX(Schedule!$D$4:$D$483,MATCH(1001,Schedule!$K$4:$K$483,0))) -> Expense | E15: =IF($B15="","",INDEX(Schedule!$E$4:$E$483,MATCH(1001,Schedule!$K$4:$K$483,0))) -> 45 | G15: =IF($B15="","",IF($D15="Income",IF($F15<>"",$F15,IF(COUNTIFS('Paid Log'!$B$9:$B$308,$C15,'Paid Log'!$C$9:$C$308,$B15)>0,SUMIFS('Paid Log'!$D$9:$D$308,'Paid Log'!$B$9:$B$308,$C15,'Paid Log'!$C$9:$C$308,$B15),$E15)),"")) | H15: =IF($B15="","",IF($D15="Income","",IF($F15<>"",$F15,IF(COUNTIFS('Paid Log'!$B$9:$B$308,$C15,'Paid Log'!$C$9:$C$308,$B15)>0,SUMIFS('Paid Log'!$D$9:$D$308,'Paid Log'!$B$9:$B$308,$C15,'Paid Log'!$C$9:$C$308,$B15),$E15)))) -> 45 | I15: =IF($B15="","",$I$13+SUMIFS($G$15:$G$65,$M$15:$M$65,"<="&$M15)-SUMIFS($H$15:$H$65,$M$15:$M$65,"<="&$M15)) -> 139.17 | J15: =IF($B15="","",IF(OR($F15<>"",COUNTIFS('Paid Log'!$B$9:$B$308,$C15,'Paid Log'!$C$9:$C$308,$B15)>0),IF($C15>TODAY(),"ADJUSTED","PAID"),IF($C15<TODAY(),"PAST DUE",IF($C15<=TODAY()+7,"DUE","Upcoming")))) -> PAID | K15: =IF($B15="","",IF(OR($F15<>"",COUNTIFS('Paid Log'!$B$9:$B$308,$C15,'Paid Log'!$C$9:$C$308,$B15)>0),"ACTUAL","FORECAST")) -> ACTUAL | L15: =IF($B15="","",$C15) -> 46250 | M15: =IF($L15="","",COUNTIFS($L$15:$L$65,"<"&$L15)+COUNTIFS($L$15:$L15,$L15)) -> 5
B16: =IFERROR(INDEX(Schedule!$C$4:$C$483,MATCH(1002,Schedule!$K$4:$K$483,0)),"") -> Bruno's Restaurant (paycheck) | C16: =IF($B16="","",INDEX(Schedule!$G$4:$G$483,MATCH(1002,Schedule!$K$4:$K$483,0))) -> 46253 | D16: =IF($B16="","",INDEX(Schedule!$D$4:$D$483,MATCH(1002,Schedule!$K$4:$K$483,0))) -> Income | E16: =IF($B16="","",INDEX(Schedule!$E$4:$E$483,MATCH(1002,Schedule!$K$4:$K$483,0))) -> 90 | G16: =IF($B16="","",IF($D16="Income",IF($F16<>"",$F16,IF(COUNTIFS('Paid Log'!$B$9:$B$308,$C16,'Paid Log'!$C$9:$C$308,$B16)>0,SUMIFS('Paid Log'!$D$9:$D$308,'Paid Log'!$B$9:$B$308,$C16,'Paid Log'!$C$9:$C$308,$B16),$E16)),"")) -> 148.34 | H16: =IF($B16="","",IF($D16="Income","",IF($F16<>"",$F16,IF(COUNTIFS('Paid Log'!$B$9:$B$308,$C16,'Paid Log'!$C$9:$C$308,$B16)>0,SUMIFS('Paid Log'!$D$9:$D$308,'Paid Log'!$B$9:$B$308,$C16,'Paid Log'!$C$9:$C$308,$B16),$E16)))) | I16: =IF($B16="","",$I$13+SUMIFS($G$15:$G$65,$M$15:$M$65,"<="&$M16)-SUMIFS($H$15:$H$65,$M$15:$M$65,"<="&$M16)) -> 119.84 | J16: =IF($B16="","",IF(OR($F16<>"",COUNTIFS('Paid Log'!$B$9:$B$308,$C16,'Paid Log'!$C$9:$C$308,$B16)>0),IF($C16>TODAY(),"ADJUSTED","PAID"),IF($C16<TODAY(),"PAST DUE",IF($C16<=TODAY()+7,"DUE","Upcoming")))) -> PAID | K16: =IF($B16="","",IF(OR($F16<>"",COUNTIFS('Paid Log'!$B$9:$B$308,$C16,'Paid Log'!$C$9:$C$308,$B16)>0),"ACTUAL","FORECAST")) -> ACTUAL | L16: =IF($B16="","",$C16) -> 46253 | M16: =IF($L16="","",COUNTIFS($L$15:$L$65,"<"&$L16)+COUNTIFS($L$15:$L16,$L16)) -> 14
